<?xml version="1.0" encoding="UTF-8"?>
<!-- Generated by org.testng.reporters.JUnitReportReporter -->
<testsuite hostname="Yutaka" name="com.sqa.ao.assertTests.TestDependancy" tests="4" failures="1" timestamp="31 Oct 2015 18:34:13 GMT" time="0.026" errors="2">
  <testcase name="testAssertEqual2" time="0.001" classname="com.sqa.ao.assertTests.TestDependancy"/>
  <testcase name="testAssertEqual3" time="0.000" classname="com.sqa.ao.assertTests.TestDependancy">
    <error type="java.lang.Throwable" message="Method TestDependancy.testAssertEqual3()[pri:0, instance:com.sqa.ao.assertTests.TestDependancy@1015293] depends on not successfully finished methods in group &quot;int&quot;">
      <![CDATA[java.lang.Throwable: Method TestDependancy.testAssertEqual3()[pri:0, instance:com.sqa.ao.assertTests.TestDependancy@1015293] depends on not successfully finished methods in group "int"
	at org.testng.internal.Invoker.invokeTestMethods(Invoker.java:1033)
	at org.testng.internal.TestMethodWorker.invokeTestMethods(TestMethodWorker.java:125)
	at org.testng.internal.TestMethodWorker.run(TestMethodWorker.java:108)
	at org.testng.TestRunner.privateRun(TestRunner.java:774)
	at org.testng.TestRunner.run(TestRunner.java:624)
	at org.testng.SuiteRunner.runTest(SuiteRunner.java:359)
	at org.testng.SuiteRunner.runSequentially(SuiteRunner.java:354)
	at org.testng.SuiteRunner.privateRun(SuiteRunner.java:312)
	at org.testng.SuiteRunner.run(SuiteRunner.java:261)
	at org.testng.SuiteRunnerWorker.runSuite(SuiteRunnerWorker.java:52)
	at org.testng.SuiteRunnerWorker.run(SuiteRunnerWorker.java:86)
	at org.testng.TestNG.runSuitesSequentially(TestNG.java:1191)
	at org.testng.TestNG.runSuitesLocally(TestNG.java:1116)
	at org.testng.TestNG.run(TestNG.java:1024)
	at org.testng.remote.RemoteTestNG.run(RemoteTestNG.java:112)
	at org.testng.remote.RemoteTestNG.initAndRun(RemoteTestNG.java:205)
	at org.testng.remote.RemoteTestNG.main(RemoteTestNG.java:176)
]]>
    </error>
  </testcase> <!-- testAssertEqual3 -->
  <testcase name="testAssertEqual1" time="0.025" classname="com.sqa.ao.assertTests.TestDependancy">
    <failure type="java.lang.AssertionError" message="expected [3] but found [1]">
      <![CDATA[java.lang.AssertionError: expected [3] but found [1]
	at org.testng.Assert.fail(Assert.java:94)
	at org.testng.Assert.failNotEquals(Assert.java:496)
	at org.testng.Assert.assertEquals(Assert.java:125)
	at org.testng.Assert.assertEquals(Assert.java:372)
	at org.testng.Assert.assertEquals(Assert.java:382)
	at com.sqa.ao.assertTests.TestDependancy.testAssertEqual1(TestDependancy.java:9)
	at sun.reflect.NativeMethodAccessorImpl.invoke0(Native Method)
	at sun.reflect.NativeMethodAccessorImpl.invoke(NativeMethodAccessorImpl.java:57)
	at sun.reflect.DelegatingMethodAccessorImpl.invoke(DelegatingMethodAccessorImpl.java:43)
	at java.lang.reflect.Method.invoke(Method.java:606)
	at org.testng.internal.MethodInvocationHelper.invokeMethod(MethodInvocationHelper.java:85)
	at org.testng.internal.Invoker.invokeMethod(Invoker.java:639)
	at org.testng.internal.Invoker.invokeTestMethod(Invoker.java:816)
	at org.testng.internal.Invoker.invokeTestMethods(Invoker.java:1124)
	at org.testng.internal.TestMethodWorker.invokeTestMethods(TestMethodWorker.java:125)
	at org.testng.internal.TestMethodWorker.run(TestMethodWorker.java:108)
	at org.testng.TestRunner.privateRun(TestRunner.java:774)
	at org.testng.TestRunner.run(TestRunner.java:624)
	at org.testng.SuiteRunner.runTest(SuiteRunner.java:359)
	at org.testng.SuiteRunner.runSequentially(SuiteRunner.java:354)
	at org.testng.SuiteRunner.privateRun(SuiteRunner.java:312)
	at org.testng.SuiteRunner.run(SuiteRunner.java:261)
	at org.testng.SuiteRunnerWorker.runSuite(SuiteRunnerWorker.java:52)
	at org.testng.SuiteRunnerWorker.run(SuiteRunnerWorker.java:86)
	at org.testng.TestNG.runSuitesSequentially(TestNG.java:1191)
	at org.testng.TestNG.runSuitesLocally(TestNG.java:1116)
	at org.testng.TestNG.run(TestNG.java:1024)
	at org.testng.remote.RemoteTestNG.run(RemoteTestNG.java:112)
	at org.testng.remote.RemoteTestNG.initAndRun(RemoteTestNG.java:205)
	at org.testng.remote.RemoteTestNG.main(RemoteTestNG.java:176)
]]>
    </failure>
  </testcase> <!-- testAssertEqual1 -->
  <testcase name="testAssertEqual4" time="0.000" classname="com.sqa.ao.assertTests.TestDependancy">
    <error type="java.lang.Throwable" message="Method TestDependancy.testAssertEqual4()[pri:0, instance:com.sqa.ao.assertTests.TestDependancy@1015293] depends on not successfully finished methods in group &quot;int&quot;">
      <![CDATA[java.lang.Throwable: Method TestDependancy.testAssertEqual4()[pri:0, instance:com.sqa.ao.assertTests.TestDependancy@1015293] depends on not successfully finished methods in group "int"
	at org.testng.internal.Invoker.invokeTestMethods(Invoker.java:1033)
	at org.testng.internal.TestMethodWorker.invokeTestMethods(TestMethodWorker.java:125)
	at org.testng.internal.TestMethodWorker.run(TestMethodWorker.java:108)
	at org.testng.TestRunner.privateRun(TestRunner.java:774)
	at org.testng.TestRunner.run(TestRunner.java:624)
	at org.testng.SuiteRunner.runTest(SuiteRunner.java:359)
	at org.testng.SuiteRunner.runSequentially(SuiteRunner.java:354)
	at org.testng.SuiteRunner.privateRun(SuiteRunner.java:312)
	at org.testng.SuiteRunner.run(SuiteRunner.java:261)
	at org.testng.SuiteRunnerWorker.runSuite(SuiteRunnerWorker.java:52)
	at org.testng.SuiteRunnerWorker.run(SuiteRunnerWorker.java:86)
	at org.testng.TestNG.runSuitesSequentially(TestNG.java:1191)
	at org.testng.TestNG.runSuitesLocally(TestNG.java:1116)
	at org.testng.TestNG.run(TestNG.java:1024)
	at org.testng.remote.RemoteTestNG.run(RemoteTestNG.java:112)
	at org.testng.remote.RemoteTestNG.initAndRun(RemoteTestNG.java:205)
	at org.testng.remote.RemoteTestNG.main(RemoteTestNG.java:176)
]]>
    </error>
  </testcase> <!-- testAssertEqual4 -->
</testsuite> <!-- com.sqa.ao.assertTests.TestDependancy -->
